:::NVLOGv0.1.0 ncf 1594346376.865880728 (ncf.py:171) cpu_info: {"num": 12, "name": "Intel(R) Core(TM) i7-9750H CPU @ 2.60GHz"}
:::NVLOGv0.1.0 ncf 1594346376.870231867 (ncf.py:171) mem_info: {"ram": "62G"}
:::NVLOGv0.1.0 ncf 1594346377.005857944 (ncf.py:171) gpu_info: {"driver_version": "440.100", "num": 1, "name": ["GeForce RTX 2080 with Max-Q Design"], "mem": ["7982 MiB"]}
:::NVLOGv0.1.0 ncf 1594346377.007677078 (ncf.py:174) args: {"data": "/data/ncf/cache/ml-20m", "epochs": 2, "batch_size": 12000, "valid_batch_size": 1048576, "factors": 64, "layers": [256, 256, 128, 64], "negative_samples": 4, "learning_rate": 0.0045, "topk": 10, "seed": 1, "threshold": 1.0, "beta1": 0.25, "beta2": 0.5, "eps": 1e-08, "dropout": 0.5, "checkpoint_dir": "/data/checkpoints/", "load_checkpoint_path": null, "mode": "train", "grads_accumulated": 1, "opt_level": "O0", "local_rank": 0, "distributed": false, "world_size": 1}
Saving results to /data/checkpoints/
:::NVLOGv0.1.0 ncf 1594346377.008574247 (ncf.py:184) preproc_hp_sample_eval_replacement: true
:::NVLOGv0.1.0 ncf 1594346377.009092093 (ncf.py:185) input_hp_sample_train_replacement: true
:::NVLOGv0.1.0 ncf 1594346377.009516478 (ncf.py:186) input_step_eval_neg_gen
:::NVLOGv0.1.0 ncf 1594346378.211468220 (ncf.py:194) run_start
Traceback (most recent call last):
  File "ncf.py", line 366, in <module>
    main()
  File "ncf.py", line 198, in main
    test_negs = torch.load(args.data+'/test_negatives.pt', map_location=torch.device('cuda:{}'.format(args.local_rank)))
  File "/opt/conda/lib/python3.6/site-packages/torch/serialization.py", line 481, in load
    with _open_file_like(f, 'rb') as opened_file:
  File "/opt/conda/lib/python3.6/site-packages/torch/serialization.py", line 210, in _open_file_like
    return _open_file(name_or_buffer, mode)
  File "/opt/conda/lib/python3.6/site-packages/torch/serialization.py", line 193, in __init__
    super(_open_file, self).__init__(open(name, mode))
FileNotFoundError: [Errno 2] No such file or directory: '/data/ncf/cache/ml-20m/test_negatives.pt'
Traceback (most recent call last):
  File "/opt/conda/lib/python3.6/runpy.py", line 193, in _run_module_as_main
    "__main__", mod_spec)
  File "/opt/conda/lib/python3.6/runpy.py", line 85, in _run_code
    exec(code, run_globals)
  File "/opt/conda/lib/python3.6/site-packages/torch/distributed/launch.py", line 253, in <module>
    main()
  File "/opt/conda/lib/python3.6/site-packages/torch/distributed/launch.py", line 249, in main
    cmd=cmd)
subprocess.CalledProcessError: Command '['/opt/conda/bin/python', '-u', 'ncf.py', '--local_rank=0', '--data', '/data/ncf/cache/ml-20m', '--epochs', '2', '--batch_size', '12000', '--opt_level', 'O0']' returned non-zero exit status 1.
DONE!
